Workbook

Sheet README
A1: AI Maturity Assessment v2: auditable scoring workbook
A2: Framework 2.0.1 · generated 2026-09-29
A4: Answers: 0 to 4 = L0 to L4; NA = not applicable (excluded); blank = not answered (excluded).
A5: Question score = AVERAGE of the respondent values.
A6: Dimension score = AVERAGE of its question scores; blank when every question is blank.
A7: Overall = SUMPRODUCT(weight, score) / sum of the weights of the dimensions that have a score.
A8: Gap = target (default 3.0) minus score, never below 0. Priority score = weight × gap.
A9: Bands: L0 [0.0, 0.8), L1 [0.8, 1.6), L2 [1.6, 2.4), L3 [2.4, 3.2), L4 [3.2, 4.0]
A10: The Engine column holds the value from output/scores.json; the formula next to it must match.

Sheet Answers
A1: Question | B1: Dimension | C1: Title | D1: R01 | E1: R02 | F1: R03 | G1: R04 | H1: R05 | I1: R06 | J1: R07 | K1: R08 | L1: R09 | M1: R10 | N1: R11 | O1: R12 | P1: R13 | Q1: R14
A2: D1-Q1 | B2: D1 | C2: Estratégia de IA para engenharia de software | D2: 3 | E2: 3 | F2: 3 | G2: 4 | H2: 3 | I2: 3 | J2: 3 | K2: 2 | L2: NA | M2: 2 | N2: 2 | O2: 3 | P2: 3 | Q2: 2
A3: D1-Q2 | B3: D1 | C3: Política de uso aceitável | D3: 3 | E3: 4 | F3: 3 | G3: 3 | H3: 3 | I3: 2 | J3: 2 | K3: 3 | L3: 3 | M3: 3 | N3: 3 | O3: 3 | P3: 3 | Q3: 3
A4: D1-Q3 | B4: D1 | C4: Ferramentas e modelos aprovados | D4: 4 | E4: NA | F4: 3 | G4: 3 | H4: 2 | I4: 2 | J4: 3 | K4: 2 | L4: NA | M4: 3 | N4: 3 | O4: 3 | P4: 2 | Q4: 3
A5: D1-Q4 | B5: D1 | C5: Proteção de dados, IP e residência | D5: 4 | E5: 4 | F5: 4 | G5: 2 | H5: 4 | I5: NA | J5: 2 | K5: 3 | L5: 2 | M5: 2 | N5: 4 | O5: 2 | P5: 3 | Q5: 4
A6: D1-Q5 | B6: D1 | C6: Níveis de autonomia para trabalho com IA | D6: 4 | E6: 3 | F6: 3 | G6: 2 | H6: 3 | I6: 2 | J6: 2 | K6: 2 | L6: 2 | M6: NA | N6: 3 | O6: 3 | P6: 2 | Q6: 4
A7: D1-Q6 | B7: D1 | C7: IA responsável e framework de risco | D7: 3 | E7: 4 | F7: 3 | G7: 3 | H7: 3 | I7: 2 | J7: 2 | K7: 2 | L7: 2 | M7: 3 | N7: 3 | O7: 2 | P7: 2 | Q7: 4
A8: D1-Q7 | B8: D1 | C8: Registro e identidade de agentes | D8: 4 | E8: 4 | F8: 3 | G8: 3 | H8: 2 | I8: 3 | J8: 3 | K8: 3 | L8: 2 | M8: 2 | N8: 2 | O8: 3 | P8: 2 | Q8: 3
A9: D2-Q1 | B9: D2 | C9: Treinamento estruturado de IA | D9: 2 | E9: 3 | F9: NA | G9: 2 | H9: 2 | I9: 2 | J9: 1 | K9: 2 | L9: 1 | M9: 2 | N9: 3 | O9: 3 | P9: 2 | Q9: 3
A10: D2-Q2 | B10: D2 | C10: Aprendizagem entre pares e champions | D10: 4 | E10: 2 | F10: 2 | G10: 2 | H10: 3 | I10: 2 | J10: 2 | K10: 2 | L10: 2 | M10: 2 | N10: 3 | O10: 2 | P10: 2 | Q10: 3
A11: D2-Q3 | B11: D2 | C11: Suporte à experimentação | D11: 3 | E11: 4 | F11: 3 | G11: 2 | H11: 2 | I11: 2 | J11: 3 | K11: 2 | L11: 1 | M11: 3 | N11: 3 | O11: 3 | P11: 2 | Q11: 3
A12: D2-Q4 | B12: D2 | C12: Habilidades de engenharia de contexto | D12: 3 | E12: 2 | F12: 3 | G12: 2 | H12: 3 | I12: 2 | J12: 2 | K12: 1 | L12: 2 | M12: 2 | N12: 2 | O12: 2 | P12: 2 | Q12: 3
A13: D2-Q5 | B13: D2 | C13: Papéis e trajetórias de carreira | D13: 3 | E13: 3 | F13: 2 | G13: 3 | H13: 2 | I13: 2 | J13: 2 | K13: 1 | L13: 1 | M13: 1 | N13: 3 | O13: 2 | P13: 3 | Q13: 3
A14: D2-Q6 | B14: D2 | C14: Onboarding assistido por IA | D14: 2 | E14: 2 | F14: 3 | G14: 3 | H14: 2 | I14: 1 | J14: 2 | K14: 2 | L14: 3 | M14: 2 | N14: 2 | O14: NA | P14: 1 | Q14: 3
A15: D3-Q1 | B15: D3 | C15: IA no refinamento de backlog | D15: 2 | E15: NA | F15: 3 | G15: 2 | H15: 2 | I15: 2 | J15: 1 | K15: 2 | L15: 2 | M15: 2 | N15: 2 | O15: 2 | P15: 1 | Q15: 3
A16: D3-Q2 | B16: D3 | C16: Especificação antes da implementação | D16: 3 | E16: 3 | F16: 2 | G16: 3 | H16: 2 | I16: 2 | J16: NA | K16: 2 | L16: 1 | M16: 1 | N16: 2 | O16: 1 | P16: 2 | Q16: NA
A17: D3-Q3 | B17: D3 | C17: Escopo de tarefas para agentes | D17: 3 | E17: 3 | F17: 2 | G17: 3 | H17: 2 | I17: 3 | J17: NA | K17: 1 | L17: 2 | M17: 2 | N17: 2 | O17: 2 | P17: 1 | Q17: 2
A18: D3-Q4 | B18: D3 | C18: Decisões de arquitetura e design | D18: 3 | E18: 2 | F18: 2 | G18: 2 | H18: NA | I18: 3 | J18: 2 | K18: 1 | L18: 2 | M18: 2 | N18: 2 | O18: 1 | P18: 3 | Q18: 3
A19: D3-Q5 | B19: D3 | C19: Foco centrado no usuário | D19: 3 | E19: 3 | F19: 2 | G19: 1 | H19: 2 | I19: 1 | J19: 2 | K19: 1 | L19: 3 | M19: 2 | N19: 2 | O19: 2 | P19: 2 | Q19: 3
A20: D3-Q6 | B20: D3 | C20: Modernização assistida por IA | D20: 2 | E20: 3 | F20: 3 | G20: 3 | H20: 2 | I20: 1 | J20: 3 | K20: 2 | L20: 2 | M20: 1 | N20: 2 | O20: 2 | P20: 1 | Q20: 3
A21: D4-Q1 | B21: D4 | C21: Profundidade do uso de IA entre superfícies | D21: 2 | E21: 4 | F21: 3 | G21: 3 | H21: 2 | I21: 2 | J21: 2 | K21: 3 | L21: 3 | M21: 2 | N21: 3 | O21: 2 | P21: NA | Q21: 3
A22: D4-Q2 | B22: D4 | C22: Modo agente para trabalho multi-file | D22: 2 | E22: 4 | F22: 4 | G22: 4 | H22: 2 | I22: 2 | J22: 2 | K22: 3 | L22: 3 | M22: 2 | N22: 3 | O22: 2 | P22: 2 | Q22: 2
A23: D4-Q3 | B23: D4 | C23: Delegação a coding agents | D23: 3 | E23: 2 | F23: 3 | G23: NA | H23: 4 | I23: NA | J23: 3 | K23: 2 | L23: 2 | M23: 3 | N23: 2 | O23: 2 | P23: 3 | Q23: 3
A24: D4-Q4 | B24: D4 | C24: Instruções de repositório | D24: 3 | E24: 2 | F24: NA | G24: 3 | H24: 2 | I24: 2 | J24: 2 | K24: 2 | L24: 3 | M24: 2 | N24: 3 | O24: 2 | P24: NA | Q24: 4
A25: D4-Q5 | B25: D4 | C25: Prompts, agentes e skills reutilizáveis | D25: 4 | E25: 3 | F25: 3 | G25: 2 | H25: 3 | I25: 3 | J25: 2 | K25: 3 | L25: 2 | M25: 3 | N25: 3 | O25: 2 | P25: 3 | Q25: 3
A26: D4-Q6 | B26: D4 | C26: Governança de MCP servers | D26: 3 | E26: 3 | F26: 4 | G26: 3 | H26: 4 | I26: 3 | J26: 3 | K26: 3 | L26: 2 | M26: 2 | N26: 3 | O26: 2 | P26: 1 | Q26: 3
A27: D4-Q7 | B27: D4 | C27: Acesso de IA ao conhecimento interno | D27: 4 | E27: 3 | F27: 4 | G27: 3 | H27: NA | I27: 3 | J27: 3 | K27: 3 | L27: 3 | M27: 2 | N27: 2 | O27: 3 | P27: NA | Q27: 4
A28: D4-Q8 | B28: D4 | C28: Seleção e roteamento de modelos | D28: 4 | E28: NA | F28: 3 | G28: 3 | H28: 2 | I28: 3 | J28: 3 | K28: 3 | L28: 2 | M28: 2 | N28: 3 | O28: 2 | P28: 3 | Q28: 2
A29: D5-Q1 | B29: D5 | C29: AI-assisted code review | D29: 2 | E29: 3 | F29: 2 | G29: 2 | H29: 3 | I29: 1 | J29: 3 | K29: 2 | L29: 2 | M29: 2 | N29: 1 | O29: 2 | P29: 1 | Q29: 3
A30: D5-Q2 | B30: D5 | C30: Human-in-the-loop para mudanças de agentes | D30: 3 | E30: 2 | F30: 3 | G30: 2 | H30: 3 | I30: 2 | J30: 3 | K30: 1 | L30: 1 | M30: 2 | N30: 2 | O30: 2 | P30: 1 | Q30: 2
A31: D5-Q3 | B31: D5 | C31: Mesmos quality gates para code de IA e humano | D31: 3 | E31: 2 | F31: 2 | G31: 2 | H31: 3 | I31: 2 | J31: 2 | K31: 2 | L31: 2 | M31: 1 | N31: 1 | O31: 1 | P31: 3 | Q31: NA
A32: D5-Q4 | B32: D5 | C32: Lotes pequenos | D32: 3 | E32: 3 | F32: 3 | G32: 2 | H32: 2 | I32: 3 | J32: 1 | K32: 2 | L32: NA | M32: 1 | N32: NA | O32: 3 | P32: 1 | Q32: 2
A33: D5-Q5 | B33: D5 | C33: Testes assistidos por IA | D33: 3 | E33: 3 | F33: 2 | G33: 2 | H33: 3 | I33: NA | J33: 3 | K33: 3 | L33: 2 | M33: 2 | N33: 1 | O33: 2 | P33: 2 | Q33: 2
A34: D5-Q6 | B34: D5 | C34: Cultura de verificação e confiança calibrada | D34: 3 | E34: NA | F34: 2 | G34: 2 | H34: 2 | I34: 1 | J34: 2 | K34: 2 | L34: 1 | M34: 1 | N34: 1 | O34: 3 | P34: 1 | Q34: 2
A35: D5-Q7 | B35: D5 | C35: Saúde do code gerado por IA | D35: 2 | E35: 3 | F35: 3 | G35: 3 | H35: 3 | I35: 2 | J35: 2 | K35: 3 | L35: 1 | M35: 1 | N35: 2 | O35: 3 | P35: 1 | Q35: 3
A36: D6-Q1 | B36: D6 | C36: Scanning de base em todo repositório | D36: 3 | E36: NA | F36: NA | G36: NA | H36: 3 | I36: NA | J36: 1 | K36: 1 | L36: NA | M36: 2 | N36: NA | O36: 2 | P36: 2 | Q36: NA
A37: D6-Q2 | B37: D6 | C37: Remediação assistida por IA | D37: 3 | E37: 2 | F37: 2 | G37: 3 | H37: NA | I37: NA | J37: 1 | K37: 2 | L37: 3 | M37: NA | N37: 1 | O37: 2 | P37: 1 | Q37: 3
A38: D6-Q3 | B38: D6 | C38: Defesas contra prompt injection para agentes | D38: 2 | E38: 3 | F38: 2 | G38: NA | H38: 2 | I38: NA | J38: NA | K38: NA | L38: 2 | M38: 2 | N38: 3 | O38: 2 | P38: NA | Q38: NA
A39: D6-Q4 | B39: D6 | C39: Least privilege para agentes | D39: 2 | E39: NA | F39: 2 | G39: 3 | H39: 1 | I39: NA | J39: 2 | K39: 1 | L39: NA | M39: NA | N39: 1 | O39: NA | P39: NA | Q39: NA
A40: D6-Q5 | B40: D6 | C40: AI supply chain | D40: NA | E40: 2 | F40: NA | G40: 2 | H40: NA | I40: NA | J40: NA | K40: 1 | L40: NA | M40: NA | N40: NA | O40: 1 | P40: NA | Q40: NA
...

Sheet Questions
A1: Question | B1: Dimension | C1: Title | D1: Score | E1: Level | F1: n | G1: NA | H1: Engine
A2: D1-Q1 | B2: D1 | C2: Estratégia de IA para engenharia de software | D2: =IF(COUNT(Answers!D2:Q2)=0,"",AVERAGE(Answers!D2:Q2)) | E2: =IF(D2="","",IF(ROUND(D2,9)<0.8,"L0",IF(ROUND(D2,9)<1.6,"L1",IF(ROUND(D2,9)<2.4,"L2",IF(ROUND(D2,9)<3.2,"L3","L4"))))) | F2: =COUNT(Answers!D2:Q2) | G2: =COUNTIF(Answers!D2:Q2,"NA") | H2: 2.769
A3: D1-Q2 | B3: D1 | C3: Política de uso aceitável | D3: =IF(COUNT(Answers!D3:Q3)=0,"",AVERAGE(Answers!D3:Q3)) | E3: =IF(D3="","",IF(ROUND(D3,9)<0.8,"L0",IF(ROUND(D3,9)<1.6,"L1",IF(ROUND(D3,9)<2.4,"L2",IF(ROUND(D3,9)<3.2,"L3","L4"))))) | F3: =COUNT(Answers!D3:Q3) | G3: =COUNTIF(Answers!D3:Q3,"NA") | H3: 2.929
A4: D1-Q3 | B4: D1 | C4: Ferramentas e modelos aprovados | D4: =IF(COUNT(Answers!D4:Q4)=0,"",AVERAGE(Answers!D4:Q4)) | E4: =IF(D4="","",IF(ROUND(D4,9)<0.8,"L0",IF(ROUND(D4,9)<1.6,"L1",IF(ROUND(D4,9)<2.4,"L2",IF(ROUND(D4,9)<3.2,"L3","L4"))))) | F4: =COUNT(Answers!D4:Q4) | G4: =COUNTIF(Answers!D4:Q4,"NA") | H4: 2.75
A5: D1-Q4 | B5: D1 | C5: Proteção de dados, IP e residência | D5: =IF(COUNT(Answers!D5:Q5)=0,"",AVERAGE(Answers!D5:Q5)) | E5: =IF(D5="","",IF(ROUND(D5,9)<0.8,"L0",IF(ROUND(D5,9)<1.6,"L1",IF(ROUND(D5,9)<2.4,"L2",IF(ROUND(D5,9)<3.2,"L3","L4"))))) | F5: =COUNT(Answers!D5:Q5) | G5: =COUNTIF(Answers!D5:Q5,"NA") | H5: 3.077
A6: D1-Q5 | B6: D1 | C6: Níveis de autonomia para trabalho com IA | D6: =IF(COUNT(Answers!D6:Q6)=0,"",AVERAGE(Answers!D6:Q6)) | E6: =IF(D6="","",IF(ROUND(D6,9)<0.8,"L0",IF(ROUND(D6,9)<1.6,"L1",IF(ROUND(D6,9)<2.4,"L2",IF(ROUND(D6,9)<3.2,"L3","L4"))))) | F6: =COUNT(Answers!D6:Q6) | G6: =COUNTIF(Answers!D6:Q6,"NA") | H6: 2.692
A7: D1-Q6 | B7: D1 | C7: IA responsável e framework de risco | D7: =IF(COUNT(Answers!D7:Q7)=0,"",AVERAGE(Answers!D7:Q7)) | E7: =IF(D7="","",IF(ROUND(D7,9)<0.8,"L0",IF(ROUND(D7,9)<1.6,"L1",IF(ROUND(D7,9)<2.4,"L2",IF(ROUND(D7,9)<3.2,"L3","L4"))))) | F7: =COUNT(Answers!D7:Q7) | G7: =COUNTIF(Answers!D7:Q7,"NA") | H7: 2.714
A8: D1-Q7 | B8: D1 | C8: Registro e identidade de agentes | D8: =IF(COUNT(Answers!D8:Q8)=0,"",AVERAGE(Answers!D8:Q8)) | E8: =IF(D8="","",IF(ROUND(D8,9)<0.8,"L0",IF(ROUND(D8,9)<1.6,"L1",IF(ROUND(D8,9)<2.4,"L2",IF(ROUND(D8,9)<3.2,"L3","L4"))))) | F8: =COUNT(Answers!D8:Q8) | G8: =COUNTIF(Answers!D8:Q8,"NA") | H8: 2.786
A9: D2-Q1 | B9: D2 | C9: Treinamento estruturado de IA | D9: =IF(COUNT(Answers!D9:Q9)=0,"",AVERAGE(Answers!D9:Q9)) | E9: =IF(D9="","",IF(ROUND(D9,9)<0.8,"L0",IF(ROUND(D9,9)<1.6,"L1",IF(ROUND(D9,9)<2.4,"L2",IF(ROUND(D9,9)<3.2,"L3","L4"))))) | F9: =COUNT(Answers!D9:Q9) | G9: =COUNTIF(Answers!D9:Q9,"NA") | H9: 2.154
A10: D2-Q2 | B10: D2 | C10: Aprendizagem entre pares e champions | D10: =IF(COUNT(Answers!D10:Q10)=0,"",AVERAGE(Answers!D10:Q10)) | E10: =IF(D10="","",IF(ROUND(D10,9)<0.8,"L0",IF(ROUND(D10,9)<1.6,"L1",IF(ROUND(D10,9)<2.4,"L2",IF(ROUND(D10,9)<3.2,"L3","L4"))))) | F10: =COUNT(Answers!D10:Q10) | G10: =COUNTIF(Answers!D10:Q10,"NA") | H10: 2.357
A11: D2-Q3 | B11: D2 | C11: Suporte à experimentação | D11: =IF(COUNT(Answers!D11:Q11)=0,"",AVERAGE(Answers!D11:Q11)) | E11: =IF(D11="","",IF(ROUND(D11,9)<0.8,"L0",IF(ROUND(D11,9)<1.6,"L1",IF(ROUND(D11,9)<2.4,"L2",IF(ROUND(D11,9)<3.2,"L3","L4"))))) | F11: =COUNT(Answers!D11:Q11) | G11: =COUNTIF(Answers!D11:Q11,"NA") | H11: 2.571
A12: D2-Q4 | B12: D2 | C12: Habilidades de engenharia de contexto | D12: =IF(COUNT(Answers!D12:Q12)=0,"",AVERAGE(Answers!D12:Q12)) | E12: =IF(D12="","",IF(ROUND(D12,9)<0.8,"L0",IF(ROUND(D12,9)<1.6,"L1",IF(ROUND(D12,9)<2.4,"L2",IF(ROUND(D12,9)<3.2,"L3","L4"))))) | F12: =COUNT(Answers!D12:Q12) | G12: =COUNTIF(Answers!D12:Q12,"NA") | H12: 2.214
A13: D2-Q5 | B13: D2 | C13: Papéis e trajetórias de carreira | D13: =IF(COUNT(Answers!D13:Q13)=0,"",AVERAGE(Answers!D13:Q13)) | E13: =IF(D13="","",IF(ROUND(D13,9)<0.8,"L0",IF(ROUND(D13,9)<1.6,"L1",IF(ROUND(D13,9)<2.4,"L2",IF(ROUND(D13,9)<3.2,"L3","L4"))))) | F13: =COUNT(Answers!D13:Q13) | G13: =COUNTIF(Answers!D13:Q13,"NA") | H13: 2.214
... A62: D9-Q7 | B62: D9 | C62: Vínculo com valor de negócio | D62: =IF(COUNT(Answers!D62:Q62)=0,"",AVERAGE(Answers!D62:Q62)) | E62: =IF(D62="","",IF(ROUND(D62,9)<0.8,"L0",IF(ROUND(D62,9)<1.6,"L1",IF(ROUND(D62,9)<2.4,"L2",IF(ROUND(D62,9)<3.2,"L3","L4"))))) | F62: =COUNT(Answers!D62:Q62) | G62: =COUNTIF(Answers!D62:Q62,"NA") | H62: 1.545

Sheet Dimensions
A1: Dimension | B1: Name | C1: Weight | D1: Score | E1: Level | F1: Target | G1: Gap | H1: Priority score | I1: Priority | J1: Engine | K1: Weight × score | L1: Counted weight
A2: D1 | B2: Estratégia, política e governança de IA | C2: 1 | D2: =IF(COUNT(Questions!D2:D8)=0,"",AVERAGE(Questions!D2:D8)) | E2: =IF(D2="","",IF(ROUND(D2,9)<0.8,"L0",IF(ROUND(D2,9)<1.6,"L1",IF(ROUND(D2,9)<2.4,"L2",IF(ROUND(D2,9)<3.2,"L3","L4"))))) | F2: 3 | G2: =IF(D2="","",MAX(0,F2-D2)) | H2: =IF(G2="","",C2*G2) | I2: =IF(H2="","",IF(ROUND(H2,9)>=2.4,"P0",IF(ROUND(H2,9)>=1.6,"P1",IF(ROUND(H2,9)>=0.9,"P2","P3")))) | J2: 2.817 | K2: =IF(D2="","",C2*D2) | L2: =IF(D2="","",C2)
A3: D2 | B3: Capacitação, habilidades e cultura | C3: 1 | D3: =IF(COUNT(Questions!D9:D14)=0,"",AVERAGE(Questions!D9:D14)) | E3: =IF(D3="","",IF(ROUND(D3,9)<0.8,"L0",IF(ROUND(D3,9)<1.6,"L1",IF(ROUND(D3,9)<2.4,"L2",IF(ROUND(D3,9)<3.2,"L3","L4"))))) | F3: 3 | G3: =IF(D3="","",MAX(0,F3-D3)) | H3: =IF(G3="","",C3*G3) | I3: =IF(H3="","",IF(ROUND(H3,9)>=2.4,"P0",IF(ROUND(H3,9)>=1.6,"P1",IF(ROUND(H3,9)>=0.9,"P2","P3")))) | J3: 2.277 | K3: =IF(D3="","",C3*D3) | L3: =IF(D3="","",C3)
A4: D3 | B4: Planejar, especificar e desenhar | C4: 1 | D4: =IF(COUNT(Questions!D15:D20)=0,"",AVERAGE(Questions!D15:D20)) | E4: =IF(D4="","",IF(ROUND(D4,9)<0.8,"L0",IF(ROUND(D4,9)<1.6,"L1",IF(ROUND(D4,9)<2.4,"L2",IF(ROUND(D4,9)<3.2,"L3","L4"))))) | F4: 3 | G4: =IF(D4="","",MAX(0,F4-D4)) | H4: =IF(G4="","",C4*G4) | I4: =IF(H4="","",IF(ROUND(H4,9)>=2.4,"P0",IF(ROUND(H4,9)>=1.6,"P1",IF(ROUND(H4,9)>=0.9,"P2","P3")))) | J4: 2.087 | K4: =IF(D4="","",C4*D4) | L4: =IF(D4="","",C4)
A5: D4 | B5: Código e engenharia de contexto | C5: 1 | D5: =IF(COUNT(Questions!D21:D28)=0,"",AVERAGE(Questions!D21:D28)) | E5: =IF(D5="","",IF(ROUND(D5,9)<0.8,"L0",IF(ROUND(D5,9)<1.6,"L1",IF(ROUND(D5,9)<2.4,"L2",IF(ROUND(D5,9)<3.2,"L3","L4"))))) | F5: 3 | G5: =IF(D5="","",MAX(0,F5-D5)) | H5: =IF(G5="","",C5*G5) | I5: =IF(H5="","",IF(ROUND(H5,9)>=2.4,"P0",IF(ROUND(H5,9)>=1.6,"P1",IF(ROUND(H5,9)>=0.9,"P2","P3")))) | J5: 2.721 | K5: =IF(D5="","",C5*D5) | L5: =IF(D5="","",C5)
A6: D5 | B6: Revisão, qualidade e testes | C6: 1 | D6: =IF(COUNT(Questions!D29:D35)=0,"",AVERAGE(Questions!D29:D35)) | E6: =IF(D6="","",IF(ROUND(D6,9)<0.8,"L0",IF(ROUND(D6,9)<1.6,"L1",IF(ROUND(D6,9)<2.4,"L2",IF(ROUND(D6,9)<3.2,"L3","L4"))))) | F6: 3 | G6: =IF(D6="","",MAX(0,F6-D6)) | H6: =IF(G6="","",C6*G6) | I6: =IF(H6="","",IF(ROUND(H6,9)>=2.4,"P0",IF(ROUND(H6,9)>=1.6,"P1",IF(ROUND(H6,9)>=0.9,"P2","P3")))) | J6: 2.096 | K6: =IF(D6="","",C6*D6) | L6: =IF(D6="","",C6)
A7: D6 | B7: Segurança e cadeia de suprimentos de IA | C7: 1 | D7: =IF(COUNT(Questions!D36:D42)=0,"",AVERAGE(Questions!D36:D42)) | E7: =IF(D7="","",IF(ROUND(D7,9)<0.8,"L0",IF(ROUND(D7,9)<1.6,"L1",IF(ROUND(D7,9)<2.4,"L2",IF(ROUND(D7,9)<3.2,"L3","L4"))))) | F7: 3 | G7: =IF(D7="","",MAX(0,F7-D7)) | H7: =IF(G7="","",C7*G7) | I7: =IF(H7="","",IF(ROUND(H7,9)>=2.4,"P0",IF(ROUND(H7,9)>=1.6,"P1",IF(ROUND(H7,9)>=0.9,"P2","P3")))) | J7: 1.895 | K7: =IF(D7="","",C7*D7) | L7: =IF(D7="","",C7)
A8: D7 | B8: Entregar e operar | C8: 1 | D8: =IF(COUNT(Questions!D43:D48)=0,"",AVERAGE(Questions!D43:D48)) | E8: =IF(D8="","",IF(ROUND(D8,9)<0.8,"L0",IF(ROUND(D8,9)<1.6,"L1",IF(ROUND(D8,9)<2.4,"L2",IF(ROUND(D8,9)<3.2,"L3","L4"))))) | F8: 3 | G8: =IF(D8="","",MAX(0,F8-D8)) | H8: =IF(G8="","",C8*G8) | I8: =IF(H8="","",IF(ROUND(H8,9)>=2.4,"P0",IF(ROUND(H8,9)>=1.6,"P1",IF(ROUND(H8,9)>=0.9,"P2","P3")))) | J8: 1.752 | K8: =IF(D8="","",C8*D8) | L8: =IF(D8="","",C8)
A9: D8 | B9: Fundamentos de engenharia (amplificadores de IA) | C9: 1 | D9: =IF(COUNT(Questions!D49:D55)=0,"",AVERAGE(Questions!D49:D55)) | E9: =IF(D9="","",IF(ROUND(D9,9)<0.8,"L0",IF(ROUND(D9,9)<1.6,"L1",IF(ROUND(D9,9)<2.4,"L2",IF(ROUND(D9,9)<3.2,"L3","L4"))))) | F9: 3 | G9: =IF(D9="","",MAX(0,F9-D9)) | H9: =IF(G9="","",C9*G9) | I9: =IF(H9="","",IF(ROUND(H9,9)>=2.4,"P0",IF(ROUND(H9,9)>=1.6,"P1",IF(ROUND(H9,9)>=0.9,"P2","P3")))) | J9: 1.088 | K9: =IF(D9="","",C9*D9) | L9: =IF(D9="","",C9)
A10: D9 | B10: Medição, valor e AI FinOps | C10: 1 | D10: =IF(COUNT(Questions!D56:D62)=0,"",AVERAGE(Questions!D56:D62)) | E10: =IF(D10="","",IF(ROUND(D10,9)<0.8,"L0",IF(ROUND(D10,9)<1.6,"L1",IF(ROUND(D10,9)<2.4,"L2",IF(ROUND(D10,9)<3.2,"L3","L4"))))) | F10: 3 | G10: =IF(D10="","",MAX(0,F10-D10)) | H10: =IF(G10="","",C10*G10) | I10: =IF(H10="","",IF(ROUND(H10,9)>=2.4,"P0",IF(ROUND(H10,9)>=1.6,"P1",IF(ROUND(H10,9)>=0.9,"P2","P3")))) | J10: 1.611 | K10: =IF(D10="","",C10*D10) | L10: =IF(D10="","",C10)

Sheet Overall
A1: Metric | B1: Value | C1: Engine
A2: Overall score | B2: =IFERROR(SUM(Dimensions!K2:K10)/SUM(Dimensions!L2:L10),"") | C2: 2.038
A3: Overall level | B3: =IF(B2="","",IF(ROUND(B2,9)<0.8,"L0",IF(ROUND(B2,9)<1.6,"L1",IF(ROUND(B2,9)<2.4,"L2",IF(ROUND(B2,9)<3.2,"L3","L4"))))) | C3: L2
A4: Questions with a score | B4: =COUNT(Questions!D2:D62) | C4: 61
A5: Coverage status | B5: =IF(B4>=37,"OK",IF(B4>=25,"WARNING","BLOCKED")) | C5: OK
A6: Respondents | B6: 14 | C6: 14
