Workbook

Sheet 📖 Como ler
B1: Pontuação e Cálculo — AI Maturity Assessment
B2: Planilha auditável com SUMPRODUCT visível
B4: Como funciona
B5: 3 camadas | C5: capability_score → pillar_score → overall_score (SUMPRODUCT em cada nível)
B6: Capability score | C6: = SUMPRODUCT(níveis × pesos) / SUM(pesos) — apenas questões respondidas entram
B7: Pillar score | C7: = SUMPRODUCT(capability_scores × pesos) / SUM(pesos) — sobre capabilities do pillar
B8: Overall score | C8: = SUMPRODUCT(TODAS capabilities × pesos) / SUM(pesos) — NÃO é média dos 3 pillars
B10: Convenção de cores
B11: Amarelo (input) | C11: Célula editável: nível selecionado, peso, target_level
B12: Azul (computed) | C12: Cálculo intermediário (nível×peso, etc.)
B13: Verde (resultado) | C13: Score final da capability/pillar/overall
B14: Rosa (target/gap) | C14: Target_level e gap_size por capability
B16: Escala
B17: L0 = 0 (Inicial) | C17: Sem prática estabelecida
B18: L1 = 1 (Em Desenvolvimento) | C18: Pilotos isolados, <25% de cobertura
B19: L2 = 2 (Definido) | C19: 25–50% de cobertura, com diretrizes
B20: L3 = 3 (Gerenciado) | C20: >75% com métricas de impacto
B21: L4 = 4 (Otimizando) | C21: >95% universal, automação contínua
B23: Mapeamento score → rótulo
B24: score < 0.5 | C24: L0 — Inicial
B25: 0.5 ≤ score < 1.5 | C25: L1 — Em Desenvolvimento
B26: 1.5 ≤ score < 2.5 | C26: L2 — Definido
B27: 2.5 ≤ score < 3.5 | C27: L3 — Gerenciado
B28: score ≥ 3.5 | C28: L4 — Otimizando
B30: Threshold de cobertura
B31: ≥ 40 questões respondidas | C31: OK — scoring confiável
B32: 25–39 questões | C32: WARNING — scoring preliminar
B33: < 25 questões | C33: BLOCKED — scoring recusado
B35: Gap analysis
B36: gap_size | C36: = target_level − current_score (descartado se ≤ 0)
B37: priority_score | C37: = peso_capability × gap_size
B38: P0 (≥ 2.4) | C38: Crítico — endereçar em 30 dias
B39: P1 (≥ 1.6) | C39: Alto — incluir no próximo trimestre
B40: P2 (≥ 0.9) | C40: Médio — backlog do semestre
B41: P3 (< 0.9) | C41: Baixo — monitorar
B43: Abas
B44: Exemplo P1 | C44: Capability P1-C1 (Assistentes de Codificação IA) — 5 questões
B45: Exemplo P2 | C45: Capability P2-C1 (Inteligência de Pipeline CI/CD) — 6 questões
B46: Exemplo P3 | C46: Capability P3-C5 (Aplicações Agênticas) — 6 questões
B47: Resumo | C47: Combina os 3 exemplos: pillar scores + overall + gap analysis

Sheet Exemplo P1 (P1-C1)
A1: P1 · P1-C1 — Assistentes de Codificação IA
A2: Pillar: Produtividade do Desenvolvedor
A4: ID Questão | B4: Pergunta (PT-BR) | C4: Nível (0-4) | D4: Rótulo | E4: Peso | F4: Nível × Peso
A5: P1-C1-Q1 | B5: Em que medida sua organização utiliza ferramentas de completação de código com IA (ex. GitHub Copilot)? | C5: 3 | D5: =IF(C5="","—",IF(C5<0.5,"L0 — Inicial",IF(C5<1.5,"L1 — Em Desenvolvimento",IF(C5<2.5,"L2 — Definido",IF(C5<3.5,"L3 — Gerenciado","L4 — Otimizando"))))) | E5: 1 | F5: =IF(C5="",0,C5*E5)
A6: P1-C1-Q2 | B6: Quão efetivamente sua equipe aproveita IA para revisão de código e melhoria de qualidade? | C6: 3 | D6: =IF(C6="","—",IF(C6<0.5,"L0 — Inicial",IF(C6<1.5,"L1 — Em Desenvolvimento",IF(C6<2.5,"L2 — Definido",IF(C6<3.5,"L3 — Gerenciado","L4 — Otimizando"))))) | E6: 1 | F6: =IF(C6="",0,C6*E6)
A7: P1-C1-Q3 | B7: Como sua organização mede e rastreia o impacto das ferramentas de codificação IA na produtividade? | C7: 2 | D7: =IF(C7="","—",IF(C7<0.5,"L0 — Inicial",IF(C7<1.5,"L1 — Em Desenvolvimento",IF(C7<2.5,"L2 — Definido",IF(C7<3.5,"L3 — Gerenciado","L4 — Otimizando"))))) | E7: 0.8 | F7: =IF(C7="",0,C7*E7)
A8: P1-C1-Q4 | B8: Qual nível de capacidades de testes assistidos por IA sua organização emprega? | C8: 4 | D8: =IF(C8="","—",IF(C8<0.5,"L0 — Inicial",IF(C8<1.5,"L1 — Em Desenvolvimento",IF(C8<2.5,"L2 — Definido",IF(C8<3.5,"L3 — Gerenciado","L4 — Otimizando"))))) | E8: 1 | F8: =IF(C8="",0,C8*E8)
A9: P1-C1-Q5 | B9: Como sua organização governa o código gerado por IA em termos de segurança e conformidade? | C9: 3 | D9: =IF(C9="","—",IF(C9<0.5,"L0 — Inicial",IF(C9<1.5,"L1 — Em Desenvolvimento",IF(C9<2.5,"L2 — Definido",IF(C9<3.5,"L3 — Gerenciado","L4 — Otimizando"))))) | E9: 1.1 | F9: =IF(C9="",0,C9*E9)
A11: Σ(Nível × Peso) | F11: =SUMPRODUCT(C5:C9,E5:E9)
A12: Σ(Peso) | F12: =SUMPRODUCT(ISNUMBER(C5:C9)*E5:E9)
A14: CAPABILITY SCORE | F14: =IF(F12=0,"",F11/F12)
A15: Rótulo de maturidade | F15: =IF(F14="","—",IF(F14<0.5,"L0 — Inicial",IF(F14<1.5,"L1 — Em Desenvolvimento",IF(F14<2.5,"L2 — Definido",IF(F14<3.5,"L3 — Gerenciado","L4 — Otimizando")))))
A17: Target level | F17: 4
A18: gap_size = target − current | F18: =IF(F14="","",MAX(0,F17-F14))
A19: Peso da capability | F19: 1.2
A20: priority_score = peso × gap | F20: =IF(F18="","",F19*F18)
A21: Prioridade | F21: =IF(F20="","",IF(F20>=2.4,"P0 — Crítico",IF(F20>=1.6,"P1 — Alto",IF(F20>=0.9,"P2 — Médio","P3 — Baixo"))))
A24: Como ler:
A25: • Células AMARELAS são editáveis — mude nível, peso da questão, peso da capability ou target.
A26: • Células AZUIS recalculam automaticamente (nível × peso, somatórios).
A27: • Célula VERDE é o resultado final da capability (com rótulo L0–L4 abaixo).
A28: • Células ROSA mostram gap analysis (target, gap, priority_score, prioridade P0–P3).
A29: • Aba 'Resumo' usa este capability_score (Cell F14) para calcular pillar e overall.

Sheet Exemplo P2 (P2-C1)
A1: P2 · P2-C1 — Inteligência de Pipeline CI/CD
A2: Pillar: Ciclo de Vida DevOps
A4: ID Questão | B4: Pergunta (PT-BR) | C4: Nível (0-4) | D4: Rótulo | E4: Peso | F4: Nível × Peso
A5: P2-C1-Q1 | B5: Quão maduro é seu pipeline CI/CD em termos de automação e integração de IA? | C5: 2 | D5: =IF(C5="","—",IF(C5<0.5,"L0 — Inicial",IF(C5<1.5,"L1 — Em Desenvolvimento",IF(C5<2.5,"L2 — Definido",IF(C5<3.5,"L3 — Gerenciado","L4 — Otimizando"))))) | E5: 1 | F5: =IF(C5="",0,C5*E5)
A6: P2-C1-Q2 | B6: Em que medida Inteligência de Pipeline CI/CD (pipeline-as-code everywhere) foi adotado entre as equipes? | C6: 3 | D6: =IF(C6="","—",IF(C6<0.5,"L0 — Inicial",IF(C6<1.5,"L1 — Em Desenvolvimento",IF(C6<2.5,"L2 — Definido",IF(C6<3.5,"L3 — Gerenciado","L4 — Otimizando"))))) | E6: 1 | F6: =IF(C6="",0,C6*E6)
A7: P2-C1-Q3 | B7: Em que medida Inteligência de Pipeline CI/CD (build caching and artifact reuse) foi adotado entre as equipes? | C7: 2 | D7: =IF(C7="","—",IF(C7<0.5,"L0 — Inicial",IF(C7<1.5,"L1 — Em Desenvolvimento",IF(C7<2.5,"L2 — Definido",IF(C7<3.5,"L3 — Gerenciado","L4 — Otimizando"))))) | E7: 1 | F7: =IF(C7="",0,C7*E7)
A8: P2-C1-Q4 | B8: Em que medida Inteligência de Pipeline CI/CD (trunk-based development) foi adotado entre as equipes? | C8: 2 | D8: =IF(C8="","—",IF(C8<0.5,"L0 — Inicial",IF(C8<1.5,"L1 — Em Desenvolvimento",IF(C8<2.5,"L2 — Definido",IF(C8<3.5,"L3 — Gerenciado","L4 — Otimizando"))))) | E8: 1 | F8: =IF(C8="",0,C8*E8)
A9: P2-C1-Q5 | B9: Em que medida Inteligência de Pipeline CI/CD (deployment frequency) foi adotado entre as equipes? | C9: 3 | D9: =IF(C9="","—",IF(C9<0.5,"L0 — Inicial",IF(C9<1.5,"L1 — Em Desenvolvimento",IF(C9<2.5,"L2 — Definido",IF(C9<3.5,"L3 — Gerenciado","L4 — Otimizando"))))) | E9: 1 | F9: =IF(C9="",0,C9*E9)
A10: P2-C1-Q6 | B10: Em que medida Inteligência de Pipeline CI/CD (feature flags for progressive delivery) foi adotado entre as equipes? | C10: 2 | D10: =IF(C10="","—",IF(C10<0.5,"L0 — Inicial",IF(C10<1.5,"L1 — Em Desenvolvimento",IF(C10<2.5,"L2 — Definido",IF(C10<3.5,"L3 — Gerenciado","L4 — Otimizando"))))) | E10: 1 | F10: =IF(C10="",0,C10*E10)
A12: Σ(Nível × Peso) | F12: =SUMPRODUCT(C5:C10,E5:E10)
A13: Σ(Peso) | F13: =SUMPRODUCT(ISNUMBER(C5:C10)*E5:E10)
A15: CAPABILITY SCORE | F15: =IF(F13=0,"",F12/F13)
A16: Rótulo de maturidade | F16: =IF(F15="","—",IF(F15<0.5,"L0 — Inicial",IF(F15<1.5,"L1 — Em Desenvolvimento",IF(F15<2.5,"L2 — Definido",IF(F15<3.5,"L3 — Gerenciado","L4 — Otimizando")))))
A18: Target level | F18: 3
A19: gap_size = target − current | F19: =IF(F15="","",MAX(0,F18-F15))
A20: Peso da capability | F20: 1.2
A21: priority_score = peso × gap | F21: =IF(F19="","",F20*F19)
A22: Prioridade | F22: =IF(F21="","",IF(F21>=2.4,"P0 — Crítico",IF(F21>=1.6,"P1 — Alto",IF(F21>=0.9,"P2 — Médio","P3 — Baixo"))))
A25: Como ler:
A26: • Células AMARELAS são editáveis — mude nível, peso da questão, peso da capability ou target.
A27: • Células AZUIS recalculam automaticamente (nível × peso, somatórios).
A28: • Célula VERDE é o resultado final da capability (com rótulo L0–L4 abaixo).
A29: • Células ROSA mostram gap analysis (target, gap, priority_score, prioridade P0–P3).
A30: • Aba 'Resumo' usa este capability_score (Cell F15) para calcular pillar e overall.

Sheet Exemplo P3 (P3-C5)
A1: P3 · P3-C5 — Aplicações Agênticas
A2: Pillar: Plataforma de Aplicações
A4: ID Questão | B4: Pergunta (PT-BR) | C4: Nível (0-4) | D4: Rótulo | E4: Peso | F4: Nível × Peso
A5: P3-C5-Q1 | B5: Em que medida Aplicações Agênticas (agents with tool-use in prod) foi adotado entre as equipes? | C5: 1 | D5: =IF(C5="","—",IF(C5<0.5,"L0 — Inicial",IF(C5<1.5,"L1 — Em Desenvolvimento",IF(C5<2.5,"L2 — Definido",IF(C5<3.5,"L3 — Gerenciado","L4 — Otimizando"))))) | E5: 1 | F5: =IF(C5="",0,C5*E5)
A6: P3-C5-Q2 | B6: Em que medida Aplicações Agênticas (orchestration framework (Semantic Kernel, etc)) foi adotado entre as equipes? | C6: 1 | D6: =IF(C6="","—",IF(C6<0.5,"L0 — Inicial",IF(C6<1.5,"L1 — Em Desenvolvimento",IF(C6<2.5,"L2 — Definido",IF(C6<3.5,"L3 — Gerenciado","L4 — Otimizando"))))) | E6: 1 | F6: =IF(C6="",0,C6*E6)
A7: P3-C5-Q3 | B7: Em que medida Aplicações Agênticas (evaluation and safety for agents) foi adotado entre as equipes? | C7: 2 | D7: =IF(C7="","—",IF(C7<0.5,"L0 — Inicial",IF(C7<1.5,"L1 — Em Desenvolvimento",IF(C7<2.5,"L2 — Definido",IF(C7<3.5,"L3 — Gerenciado","L4 — Otimizando"))))) | E7: 1 | F7: =IF(C7="",0,C7*E7)
A8: P3-C5-Q4 | B8: Em que medida Aplicações Agênticas (tool/action registry) foi adotado entre as equipes? | C8: 0 | D8: =IF(C8="","—",IF(C8<0.5,"L0 — Inicial",IF(C8<1.5,"L1 — Em Desenvolvimento",IF(C8<2.5,"L2 — Definido",IF(C8<3.5,"L3 — Gerenciado","L4 — Otimizando"))))) | E8: 1 | F8: =IF(C8="",0,C8*E8)
A9: P3-C5-Q5 | B9: Em que medida Aplicações Agênticas (human-in-the-loop controls) foi adotado entre as equipes? | C9: 1 | D9: =IF(C9="","—",IF(C9<0.5,"L0 — Inicial",IF(C9<1.5,"L1 — Em Desenvolvimento",IF(C9<2.5,"L2 — Definido",IF(C9<3.5,"L3 — Gerenciado","L4 — Otimizando"))))) | E9: 1 | F9: =IF(C9="",0,C9*E9)
A10: P3-C5-Q6 | B10: Em que medida Aplicações Agênticas (agent cost and latency telemetry) foi adotado entre as equipes? | C10: 0 | D10: =IF(C10="","—",IF(C10<0.5,"L0 — Inicial",IF(C10<1.5,"L1 — Em Desenvolvimento",IF(C10<2.5,"L2 — Definido",IF(C10<3.5,"L3 — Gerenciado","L4 — Otimizando"))))) | E10: 1 | F10: =IF(C10="",0,C10*E10)
A12: Σ(Nível × Peso) | F12: =SUMPRODUCT(C5:C10,E5:E10)
A13: Σ(Peso) | F13: =SUMPRODUCT(ISNUMBER(C5:C10)*E5:E10)
A15: CAPABILITY SCORE | F15: =IF(F13=0,"",F12/F13)
A16: Rótulo de maturidade | F16: =IF(F15="","—",IF(F15<0.5,"L0 — Inicial",IF(F15<1.5,"L1 — Em Desenvolvimento",IF(F15<2.5,"L2 — Definido",IF(F15<3.5,"L3 — Gerenciado","L4 — Otimizando")))))
A18: Target level | F18: 4
A19: gap_size = target − current | F19: =IF(F15="","",MAX(0,F18-F15))
A20: Peso da capability | F20: 1
A21: priority_score = peso × gap | F21: =IF(F19="","",F20*F19)
A22: Prioridade | F22: =IF(F21="","",IF(F21>=2.4,"P0 — Crítico",IF(F21>=1.6,"P1 — Alto",IF(F21>=0.9,"P2 — Médio","P3 — Baixo"))))
A25: Como ler:
A26: • Células AMARELAS são editáveis — mude nível, peso da questão, peso da capability ou target.
A27: • Células AZUIS recalculam automaticamente (nível × peso, somatórios).
A28: • Célula VERDE é o resultado final da capability (com rótulo L0–L4 abaixo).
A29: • Células ROSA mostram gap analysis (target, gap, priority_score, prioridade P0–P3).
A30: • Aba 'Resumo' usa este capability_score (Cell F15) para calcular pillar e overall.

Sheet 📊 Resumo (Pillar + Overall)
B1: Resumo de Pontuação — Combinando os 3 exemplos
B2: Pillar score = SUMPRODUCT(capability × peso) / SUM(peso). Overall = SUMPRODUCT sobre TODAS capabilities.
B4: Pillar | C4: Capability | D4: Capability Score | E4: Peso Capability | F4: score × peso | G4: Target | H4: Gap | I4: Priority
B5: P1 | C5: P1-C1 — Assistentes de Codificação IA | D5: =IFERROR('Exemplo P1 (P1-C1)'!F14,"") | E5: ='Exemplo P1 (P1-C1)'!F19 | F5: =IF(D5="",0,D5*E5) | G5: 4 | H5: =IF(D5="","",MAX(0,G5-D5)) | I5: =IF(H5="","",IF(E5*H5>=2.4,"P0",IF(E5*H5>=1.6,"P1",IF(E5*H5>=0.9,"P2","P3"))))
B6: P2 | C6: P2-C1 — Inteligência de Pipeline CI/CD | D6: =IFERROR('Exemplo P2 (P2-C1)'!F15,"") | E6: ='Exemplo P2 (P2-C1)'!F20 | F6: =IF(D6="",0,D6*E6) | G6: 3 | H6: =IF(D6="","",MAX(0,G6-D6)) | I6: =IF(H6="","",IF(E6*H6>=2.4,"P0",IF(E6*H6>=1.6,"P1",IF(E6*H6>=0.9,"P2","P3"))))
B7: P3 | C7: P3-C5 — Aplicações Agênticas | D7: =IFERROR('Exemplo P3 (P3-C5)'!F15,"") | E7: ='Exemplo P3 (P3-C5)'!F20 | F7: =IF(D7="",0,D7*E7) | G7: 4 | H7: =IF(D7="","",MAX(0,G7-D7)) | I7: =IF(H7="","",IF(E7*H7>=2.4,"P0",IF(E7*H7>=1.6,"P1",IF(E7*H7>=0.9,"P2","P3"))))
B10: Pillar Scores
B11: P1 | C11: P1 — Produtividade do Desenvolvedor | D11: =IFERROR(F5/E5,"") | E11: =IF(D11<0.5,"L0",IF(D11<1.5,"L1",IF(D11<2.5,"L2",IF(D11<3.5,"L3","L4"))))
B12: P2 | C12: P2 — Ciclo de Vida DevOps | D12: =IFERROR(F6/E6,"") | E12: =IF(D12<0.5,"L0",IF(D12<1.5,"L1",IF(D12<2.5,"L2",IF(D12<3.5,"L3","L4"))))
B13: P3 | C13: P3 — Plataforma de Aplicações | D13: =IFERROR(F7/E7,"") | E13: =IF(D13<0.5,"L0",IF(D13<1.5,"L1",IF(D13<2.5,"L2",IF(D13<3.5,"L3","L4"))))
B15: OVERALL SCORE | D15: =IFERROR(SUMPRODUCT(D5:D7,E5:E7)/SUM(E5:E7),"") | E15: =IF(D15<0.5,"L0 — Inicial",IF(D15<1.5,"L1 — Em Desenvolvimento",IF(D15<2.5,"L2 — Definido",IF(D15<3.5,"L3 — Gerenciado","L4 — Otimizando"))))
B18: Fórmulas usadas:
B19: • Pillar score (1 cap por pillar nesta demo): = score × peso / peso (no caso real: SUMPRODUCT sobre todas as capabilities do pillar)
B20: • Overall: =SUMPRODUCT(D5:D7; E5:E7) / SUM(E5:E7)
B22: Observação:
B23: • Na plataforma real, cada pillar tem ~9-10 capabilities. O Overall NÃO é média dos 3 pillars — é SUMPRODUCT direto.
B24: • Capabilities sem nenhuma resposta (capability_score = NULL) são ignoradas no Overall e no Pillar.
B25: • Pesos default são 1.0 (range permitido [0.5, 2.0]).

Sheet Respostas
A1: ID Questão | B1: Pilar | C1: Capability | D1: Pergunta | E1: Nível (0-4) | F1: Peso | G1: Respondida | H1: Nível × Peso | I1: Rótulo | J1: Evidência
A2: P1-C1-Q1 | B2: P1 | C2: P1-C1 | D2: Em que medida sua organização utiliza ferramentas de completação de código com IA (ex. GitHub Copilot)? | E2: 3 | F2: 1 | G2: =IF(E2="",0,1) | H2: =IF(G2=1,E2*F2,0) | I2: =IF(E2="","—",IF(E2<0.5,"L0 — Inicial",IF(E2<1.5,"L1 — Em Desenvolvimento",IF(E2<2.5,"L2 — Definido",IF(E2<3.5,"L3 — Gerenciado","L4 — Otimizando"))))) | J2: Cobertura de 80%+ com métricas mostrando ganhos consistentes (~20% velocidade).
A3: P1-C1-Q2 | B3: P1 | C3: P1-C1 | D3: Quão efetivamente sua equipe aproveita IA para revisão de código e melhoria de qualidade? | E3: 3 | F3: 1 | G3: =IF(E3="",0,1) | H3: =IF(G3=1,E3*F3,0) | I3: =IF(E3="","—",IF(E3<0.5,"L0 — Inicial",IF(E3<1.5,"L1 — Em Desenvolvimento",IF(E3<2.5,"L2 — Definido",IF(E3<3.5,"L3 — Gerenciado","L4 — Otimizando"))))) | J3: Programa maduro com ~85% cobertura, dashboards Grafana ativos e revisão trimestral.
A4: P1-C1-Q3 | B4: P1 | C4: P1-C1 | D4: Como sua organização mede e rastreia o impacto das ferramentas de codificação IA na produtividade? | E4: 2 | F4: 0.8 | G4: =IF(E4="",0,1) | H4: =IF(G4=1,E4*F4,0) | I4: =IF(E4="","—",IF(E4<0.5,"L0 — Inicial",IF(E4<1.5,"L1 — Em Desenvolvimento",IF(E4<2.5,"L2 — Definido",IF(E4<3.5,"L3 — Gerenciado","L4 — Otimizando"))))) | J4: Aproximadamente 45% de adoção, com workshops mensais e métricas iniciais.
A5: P1-C1-Q4 | B5: P1 | C5: P1-C1 | D5: Qual nível de capacidades de testes assistidos por IA sua organização emprega? | E5: 4 | F5: 1 | G5: =IF(E5="",0,1) | H5: =IF(G5=1,E5*F5,0) | I5: =IF(E5="","—",IF(E5<0.5,"L0 — Inicial",IF(E5<1.5,"L1 — Em Desenvolvimento",IF(E5<2.5,"L2 — Definido",IF(E5<3.5,"L3 — Gerenciado","L4 — Otimizando"))))) | J5: Adoção universal (>95%) com fine-tuning customizado e ganhos medidos >35%.
A6: P1-C1-Q5 | B6: P1 | C6: P1-C1 | D6: Como sua organização governa o código gerado por IA em termos de segurança e conformidade? | E6: 3 | F6: 1.1 | G6: =IF(E6="",0,1) | H6: =IF(G6=1,E6*F6,0) | I6: =IF(E6="","—",IF(E6<0.5,"L0 — Inicial",IF(E6<1.5,"L1 — Em Desenvolvimento",IF(E6<2.5,"L2 — Definido",IF(E6<3.5,"L3 — Gerenciado","L4 — Otimizando"))))) | J6: Adoção em mais de 75% dos squads; biblioteca de templates compartilhada e métricas DORA monitoradas.
A7: P1-C2-Q1 | B7: P1 | C7: P1-C2 | D7: Quão maduro é seu portal ou plataforma interna para desenvolvedores? | E7: 2 | F7: 1 | G7: =IF(E7="",0,1) | H7: =IF(G7=1,E7*F7,0) | I7: =IF(E7="","—",IF(E7<0.5,"L0 — Inicial",IF(E7<1.5,"L1 — Em Desenvolvimento",IF(E7<2.5,"L2 — Definido",IF(E7<3.5,"L3 — Gerenciado","L4 — Otimizando"))))) | J7: Implantação em 35% dos serviços; documentação publicada no Confluence interno.
A8: P1-C2-Q2 | B8: P1 | C8: P1-C2 | D8: Quão efetivamente suas equipes usam ambientes de desenvolvimento padronizados? | E8: 3 | F8: 0.9 | G8: =IF(E8="",0,1) | H8: =IF(G8=1,E8*F8,0) | I8: =IF(E8="","—",IF(E8<0.5,"L0 — Inicial",IF(E8<1.5,"L1 — Em Desenvolvimento",IF(E8<2.5,"L2 — Definido",IF(E8<3.5,"L3 — Gerenciado","L4 — Otimizando"))))) | J8: Adoção em mais de 75% dos squads; biblioteca de templates compartilhada e métricas DORA monitoradas.
A9: P1-C2-Q3 | B9: P1 | C9: P1-C2 | D9: Em que medida Plataforma de Experiência do Desenvolvedor (self-service IDP) foi adotado entre as equipes? | E9: 2 | F9: 1 | G9: =IF(E9="",0,1) | H9: =IF(G9=1,E9*F9,0) | I9: =IF(E9="","—",IF(E9<0.5,"L0 — Inicial",IF(E9<1.5,"L1 — Em Desenvolvimento",IF(E9<2.5,"L2 — Definido",IF(E9<3.5,"L3 — Gerenciado","L4 — Otimizando"))))) | J9: Implantação em 35% dos serviços; documentação publicada no Confluence interno.
A10: P1-C2-Q4 | B10: P1 | C10: P1-C2 | D10: Em que medida Plataforma de Experiência do Desenvolvedor (golden paths and templates) foi adotado entre as equipes? | E10: 3 | F10: 1 | G10: =IF(E10="",0,1) | H10: =IF(G10=1,E10*F10,0) | I10: =IF(E10="","—",IF(E10<0.5,"L0 — Inicial",IF(E10<1.5,"L1 — Em Desenvolvimento",IF(E10<2.5,"L2 — Definido",IF(E10<3.5,"L3 — Gerenciado","L4 — Otimizando"))))) | J10: Programa maduro com ~85% cobertura, dashboards Grafana ativos e revisão trimestral.
A11: P1-C2-Q5 | B11: P1 | C11: P1-C2 | D11: Em que medida Plataforma de Experiência do Desenvolvedor (developer portal) foi adotado entre as equipes? | F11: 1 | G11: =IF(E11="",0,1) | H11: =IF(G11=1,E11*F11,0) | I11: =IF(E11="","—",IF(E11<0.5,"L0 — Inicial",IF(E11<1.5,"L1 — Em Desenvolvimento",IF(E11<2.5,"L2 — Definido",IF(E11<3.5,"L3 — Gerenciado","L4 — Otimizando")))))
A12: P1-C2-Q6 | B12: P1 | C12: P1-C2 | D12: Em que medida Plataforma de Experiência do Desenvolvedor (paved road policy enforcement) foi adotado entre as equipes? | F12: 1 | G12: =IF(E12="",0,1) | H12: =IF(G12=1,E12*F12,0) | I12: =IF(E12="","—",IF(E12<0.5,"L0 — Inicial",IF(E12<1.5,"L1 — Em Desenvolvimento",IF(E12<2.5,"L2 — Definido",IF(E12<3.5,"L3 — Gerenciado","L4 — Otimizando")))))
A13: P1-C3-Q1 | B13: P1 | C13: P1-C3 | D13: Quão efetivamente sua organização captura e compartilha conhecimento de desenvolvimento? | F13: 1 | G13: =IF(E13="",0,1) | H13: =IF(G13=1,E13*F13,0) | I13: =IF(E13="","—",IF(E13<0.5,"L0 — Inicial",IF(E13<1.5,"L1 — Em Desenvolvimento",IF(E13<2.5,"L2 — Definido",IF(E13<3.5,"L3 — Gerenciado","L4 — Otimizando")))))
A14: P1-C3-Q2 | B14: P1 | C14: P1-C3 | D14: Em que medida Gestão do Conhecimento (semantic code search) foi adotado entre as equipes? | F14: 1 | G14: =IF(E14="",0,1) | H14: =IF(G14=1,E14*F14,0) | I14: =IF(E14="","—",IF(E14<0.5,"L0 — Inicial",IF(E14<1.5,"L1 — Em Desenvolvimento",IF(E14<2.5,"L2 — Definido",IF(E14<3.5,"L3 — Gerenciado","L4 — Otimizando")))))
A15: P1-C3-Q3 | B15: P1 | C15: P1-C3 | D15: Em que medida Gestão do Conhecimento (RAG-based docs assistant) foi adotado entre as equipes? | F15: 1 | G15: =IF(E15="",0,1) | H15: =IF(G15=1,E15*F15,0) | I15: =IF(E15="","—",IF(E15<0.5,"L0 — Inicial",IF(E15<1.5,"L1 — Em Desenvolvimento",IF(E15<2.5,"L2 — Definido",IF(E15<3.5,"L3 — Gerenciado","L4 — Otimizando")))))
A16: P1-C3-Q4 | B16: P1 | C16: P1-C3 | D16: Em que medida Gestão do Conhecimento (runbook and playbook coverage) foi adotado entre as equipes? | F16: 1 | G16: =IF(E16="",0,1) | H16: =IF(G16=1,E16*F16,0) | I16: =IF(E16="","—",IF(E16<0.5,"L0 — Inicial",IF(E16<1.5,"L1 — Em Desenvolvimento",IF(E16<2.5,"L2 — Definido",IF(E16<3.5,"L3 — Gerenciado","L4 — Otimizando")))))
A17: P1-C3-Q5 | B17: P1 | C17: P1-C3 | D17: Em que medida Gestão do Conhecimento (ADR (architecture decision records)) foi adotado entre as equipes? | F17: 1 | G17: =IF(E17="",0,1) | H17: =IF(G17=1,E17*F17,0) | I17: =IF(E17="","—",IF(E17<0.5,"L0 — Inicial",IF(E17<1.5,"L1 — Em Desenvolvimento",IF(E17<2.5,"L2 — Definido",IF(E17<3.5,"L3 — Gerenciado","L4 — Otimizando")))))
A18: P1-C3-Q6 | B18: P1 | C18: P1-C3 | D18: Em que medida Gestão do Conhecimento (learning content & curated paths) foi adotado entre as equipes? | F18: 1 | G18: =IF(E18="",0,1) | H18: =IF(G18=1,E18*F18,0) | I18: =IF(E18="","—",IF(E18<0.5,"L0 — Inicial",IF(E18<1.5,"L1 — Em Desenvolvimento",IF(E18<2.5,"L2 — Definido",IF(E18<3.5,"L3 — Gerenciado","L4 — Otimizando")))))
A19: P1-C4-Q1 | B19: P1 | C19: P1-C4 | D19: Em que medida Automação de Revisão de Código (AI reviewer bot on every PR) foi adotado entre as equipes? | E19: 3 | F19: 1 | G19: =IF(E19="",0,1) | H19: =IF(G19=1,E19*F19,0) | I19: =IF(E19="","—",IF(E19<0.5,"L0 — Inicial",IF(E19<1.5,"L1 — Em Desenvolvimento",IF(E19<2.5,"L2 — Definido",IF(E19<3.5,"L3 — Gerenciado","L4 — Otimizando"))))) | J19: Programa maduro com ~85% cobertura, dashboards Grafana ativos e revisão trimestral.
A20: P1-C4-Q2 | B20: P1 | C20: P1-C4 | D20: Em que medida Automação de Revisão de Código (static linting and style auto-fix) foi adotado entre as equipes? | E20: 2 | F20: 1 | G20: =IF(E20="",0,1) | H20: =IF(G20=1,E20*F20,0) | I20: =IF(E20="","—",IF(E20<0.5,"L0 — Inicial",IF(E20<1.5,"L1 — Em Desenvolvimento",IF(E20<2.5,"L2 — Definido",IF(E20<3.5,"L3 — Gerenciado","L4 — Otimizando"))))) | J20: Cobertura de ~40% das equipes com diretrizes escritas e treinamento básico.
A21: P1-C4-Q3 | B21: P1 | C21: P1-C4 | D21: Em que medida Automação de Revisão de Código (automated security review) foi adotado entre as equipes? | E21: 3 | F21: 1 | G21: =IF(E21="",0,1) | H21: =IF(G21=1,E21*F21,0) | I21: =IF(E21="","—",IF(E21<0.5,"L0 — Inicial",IF(E21<1.5,"L1 — Em Desenvolvimento",IF(E21<2.5,"L2 — Definido",IF(E21<3.5,"L3 — Gerenciado","L4 — Otimizando"))))) | J21: Cobertura de 80%+ com métricas mostrando ganhos consistentes (~20% velocidade).
A22: P1-C4-Q4 | B22: P1 | C22: P1-C4 | D22: Em que medida Automação de Revisão de Código (required-reviewer rules) foi adotado entre as equipes? | E22: 2 | F22: 1 | G22: =IF(E22="",0,1) | H22: =IF(G22=1,E22*F22,0) | I22: =IF(E22="","—",IF(E22<0.5,"L0 — Inicial",IF(E22<1.5,"L1 — Em Desenvolvimento",IF(E22<2.5,"L2 — Definido",IF(E22<3.5,"L3 — Gerenciado","L4 — Otimizando"))))) | J22: Cobertura de ~40% das equipes com diretrizes escritas e treinamento básico.
A23: P1-C4-Q5 | B23: P1 | C23: P1-C4 | D23: Em que medida Automação de Revisão de Código (review SLA tracking) foi adotado entre as equipes? | F23: 1 | G23: =IF(E23="",0,1) | H23: =IF(G23=1,E23*F23,0) | I23: =IF(E23="","—",IF(E23<0.5,"L0 — Inicial",IF(E23<1.5,"L1 — Em Desenvolvimento",IF(E23<2.5,"L2 — Definido",IF(E23<3.5,"L3 — Gerenciado","L4 — Otimizando")))))
A24: P1-C4-Q6 | B24: P1 | C24: P1-C4 | D24: Em que medida Automação de Revisão de Código (change size enforcement) foi adotado entre as equipes? | F24: 1 | G24: =IF(E24="",0,1) | H24: =IF(G24=1,E24*F24,0) | I24: =IF(E24="","—",IF(E24<0.5,"L0 — Inicial",IF(E24<1.5,"L1 — Em Desenvolvimento",IF(E24<2.5,"L2 — Definido",IF(E24<3.5,"L3 — Gerenciado","L4 — Otimizando")))))
A25: P1-C4-Q7 | B25: P1 | C25: P1-C4 | D25: Em que medida Automação de Revisão de Código (reviewer load balancing) foi adotado entre as equipes? | F25: 1 | G25: =IF(E25="",0,1) | H25: =IF(G25=1,E25*F25,0) | I25: =IF(E25="","—",IF(E25<0.5,"L0 — Inicial",IF(E25<1.5,"L1 — Em Desenvolvimento",IF(E25<2.5,"L2 — Definido",IF(E25<3.5,"L3 — Gerenciado","L4 — Otimizando")))))
A26: P1-C5-Q1 | B26: P1 | C26: P1-C5 | D26: Em que medida Onboarding e Treinamento de Desenvolvedores (codespaces/dev containers for instant env) foi adotado entre as equipes? | F26: 1 | G26: =IF(E26="",0,1) | H26: =IF(G26=1,E26*F26,0) | I26: =IF(E26="","—",IF(E26<0.5,"L0 — Inicial",IF(E26<1.5,"L1 — Em Desenvolvimento",IF(E26<2.5,"L2 — Definido",IF(E26<3.5,"L3 — Gerenciado","L4 — Otimizando")))))
A27: P1-C5-Q2 | B27: P1 | C27: P1-C5 | D27: Em que medida Onboarding e Treinamento de Desenvolvedores (structured onboarding playbook) foi adotado entre as equipes? | F27: 1 | G27: =IF(E27="",0,1) | H27: =IF(G27=1,E27*F27,0) | I27: =IF(E27="","—",IF(E27<0.5,"L0 — Inicial",IF(E27<1.5,"L1 — Em Desenvolvimento",IF(E27<2.5,"L2 — Definido",IF(E27<3.5,"L3 — Gerenciado","L4 — Otimizando")))))
A28: P1-C5-Q3 | B28: P1 | C28: P1-C5 | D28: Em que medida Onboarding e Treinamento de Desenvolvedores (mentor pairing program) foi adotado entre as equipes? | F28: 1 | G28: =IF(E28="",0,1) | H28: =IF(G28=1,E28*F28,0) | I28: =IF(E28="","—",IF(E28<0.5,"L0 — Inicial",IF(E28<1.5,"L1 — Em Desenvolvimento",IF(E28<2.5,"L2 — Definido",IF(E28<3.5,"L3 — Gerenciado","L4 — Otimizando")))))
A29: P1-C5-Q4 | B29: P1 | C29: P1-C5 | D29: Em que medida Onboarding e Treinamento de Desenvolvedores (hands-on curriculum & kata) foi adotado entre as equipes? | F29: 1 | G29: =IF(E29="",0,1) | H29: =IF(G29=1,E29*F29,0) | I29: =IF(E29="","—",IF(E29<0.5,"L0 — Inicial",IF(E29<1.5,"L1 — Em Desenvolvimento",IF(E29<2.5,"L2 — Definido",IF(E29<3.5,"L3 — Gerenciado","L4 — Otimizando")))))
A30: P1-C5-Q5 | B30: P1 | C30: P1-C5 | D30: Em que medida Onboarding e Treinamento de Desenvolvedores (shadow on-call rotation) foi adotado entre as equipes? | F30: 1 | G30: =IF(E30="",0,1) | H30: =IF(G30=1,E30*F30,0) | I30: =IF(E30="","—",IF(E30<0.5,"L0 — Inicial",IF(E30<1.5,"L1 — Em Desenvolvimento",IF(E30<2.5,"L2 — Definido",IF(E30<3.5,"L3 — Gerenciado","L4 — Otimizando")))))
A31: P1-C5-Q6 | B31: P1 | C31: P1-C5 | D31: Em que medida Onboarding e Treinamento de Desenvolvedores (onboarding feedback loop) foi adotado entre as equipes? | F31: 1 | G31: =IF(E31="",0,1) | H31: =IF(G31=1,E31*F31,0) | I31: =IF(E31="","—",IF(E31<0.5,"L0 — Inicial",IF(E31<1.5,"L1 — Em Desenvolvimento",IF(E31<2.5,"L2 — Definido",IF(E31<3.5,"L3 — Gerenciado","L4 — Otimizando")))))
A32: P1-C5-Q7 | B32: P1 | C32: P1-C5 | D32: Em que medida Onboarding e Treinamento de Desenvolvedores (ramp-time measurement) foi adotado entre as equipes? | F32: 1 | G32: =IF(E32="",0,1) | H32: =IF(G32=1,E32*F32,0) | I32: =IF(E32="","—",IF(E32<0.5,"L0 — Inicial",IF(E32<1.5,"L1 — Em Desenvolvimento",IF(E32<2.5,"L2 — Definido",IF(E32<3.5,"L3 — Gerenciado","L4 — Otimizando")))))
A33: P1-C6-Q1 | B33: P1 | C33: P1-C6 | D33: Em que medida Inner Source e Colaboração (internal repos with open contribution) foi adotado entre as equipes? | F33: 1 | G33: =IF(E33="",0,1) | H33: =IF(G33=1,E33*F33,0) | I33: =IF(E33="","—",IF(E33<0.5,"L0 — Inicial",IF(E33<1.5,"L1 — Em Desenvolvimento",IF(E33<2.5,"L2 — Definido",IF(E33<3.5,"L3 — Gerenciado","L4 — Otimizando")))))
A34: P1-C6-Q2 | B34: P1 | C34: P1-C6 | D34: Em que medida Inner Source e Colaboração (CONTRIBUTING.md standards) foi adotado entre as equipes? | F34: 1 | G34: =IF(E34="",0,1) | H34: =IF(G34=1,E34*F34,0) | I34: =IF(E34="","—",IF(E34<0.5,"L0 — Inicial",IF(E34<1.5,"L1 — Em Desenvolvimento",IF(E34<2.5,"L2 — Definido",IF(E34<3.5,"L3 — Gerenciado","L4 — Otimizando")))))
... A54: P1-C9-Q5 | B54: P1 | C54: P1-C9 | D54: Em que medida Automação de Ambientes e Espaços de Trabalho (workspace telemetry & health) foi adotado entre as equipes? | F54: 1 | G54: =IF(E54="",0,1) | H54: =IF(G54=1,E54*F54,0) | I54: =IF(E54="","—",IF(E54<0.5,"L0 — Inicial",IF(E54<1.5,"L1 — Em Desenvolvimento",IF(E54<2.5,"L2 — Definido",IF(E54<3.5,"L3 — Gerenciado","L4 — Otimizando")))))
A55: P2-C1-Q1 | B55: P2 | C55: P2-C1 | D55: Quão maduro é seu pipeline CI/CD em termos de automação e integração de IA? | E55: 2 | F55: 1 | G55: =IF(E55="",0,1) | H55: =IF(G55=1,E55*F55,0) | I55: =IF(E55="","—",IF(E55<0.5,"L0 — Inicial",IF(E55<1.5,"L1 — Em Desenvolvimento",IF(E55<2.5,"L2 — Definido",IF(E55<3.5,"L3 — Gerenciado","L4 — Otimizando"))))) | J55: Aproximadamente 45% de adoção, com workshops mensais e métricas iniciais.
A56: P2-C1-Q2 | B56: P2 | C56: P2-C1 | D56: Em que medida Inteligência de Pipeline CI/CD (pipeline-as-code everywhere) foi adotado entre as equipes? | E56: 3 | F56: 1 | G56: =IF(E56="",0,1) | H56: =IF(G56=1,E56*F56,0) | I56: =IF(E56="","—",IF(E56<0.5,"L0 — Inicial",IF(E56<1.5,"L1 — Em Desenvolvimento",IF(E56<2.5,"L2 — Definido",IF(E56<3.5,"L3 — Gerenciado","L4 — Otimizando"))))) | J56: Adoção em mais de 75% dos squads; biblioteca de templates compartilhada e métricas DORA monitoradas.
A57: P2-C1-Q3 | B57: P2 | C57: P2-C1 | D57: Em que medida Inteligência de Pipeline CI/CD (build caching and artifact reuse) foi adotado entre as equipes? | E57: 2 | F57: 1 | G57: =IF(E57="",0,1) | H57: =IF(G57=1,E57*F57,0) | I57: =IF(E57="","—",IF(E57<0.5,"L0 — Inicial",IF(E57<1.5,"L1 — Em Desenvolvimento",IF(E57<2.5,"L2 — Definido",IF(E57<3.5,"L3 — Gerenciado","L4 — Otimizando"))))) | J57: Implantação em 35% dos serviços; documentação publicada no Confluence interno.
A58: P2-C1-Q4 | B58: P2 | C58: P2-C1 | D58: Em que medida Inteligência de Pipeline CI/CD (trunk-based development) foi adotado entre as equipes? | E58: 2 | F58: 1 | G58: =IF(E58="",0,1) | H58: =IF(G58=1,E58*F58,0) | I58: =IF(E58="","—",IF(E58<0.5,"L0 — Inicial",IF(E58<1.5,"L1 — Em Desenvolvimento",IF(E58<2.5,"L2 — Definido",IF(E58<3.5,"L3 — Gerenciado","L4 — Otimizando"))))) | J58: Cobertura de ~40% das equipes com diretrizes escritas e treinamento básico.
A59: P2-C1-Q5 | B59: P2 | C59: P2-C1 | D59: Em que medida Inteligência de Pipeline CI/CD (deployment frequency) foi adotado entre as equipes? | E59: 3 | F59: 1 | G59: =IF(E59="",0,1) | H59: =IF(G59=1,E59*F59,0) | I59: =IF(E59="","—",IF(E59<0.5,"L0 — Inicial",IF(E59<1.5,"L1 — Em Desenvolvimento",IF(E59<2.5,"L2 — Definido",IF(E59<3.5,"L3 — Gerenciado","L4 — Otimizando"))))) | J59: Adoção em mais de 75% dos squads; biblioteca de templates compartilhada e métricas DORA monitoradas.
...

Sheet Capabilities
A1: Capability | B1: Nome | C1: Pilar | D1: Peso | E1: Respondidas | F1: Σ(Nível × Peso) | G1: Σ(Peso respondidas) | H1: Score | I1: Rótulo | J1: Target | K1: Gap | L1: Priority score | M1: Prioridade | N1: Score × Peso | O1: Peso se pontuada
A2: P1-C1 | B2: Assistentes de Codificação IA | C2: P1 | D2: 1.2 | E2: =COUNTIFS('Respostas'!$C$2:$C$159,A2,'Respostas'!$G$2:$G$159,1) | F2: =SUMIFS('Respostas'!$H$2:$H$159,'Respostas'!$C$2:$C$159,A2) | G2: =SUMIFS('Respostas'!$F$2:$F$159,'Respostas'!$C$2:$C$159,A2,'Respostas'!$G$2:$G$159,1) | H2: =IF(G2=0,"",F2/G2) | I2: =IF(H2="","—",IF(H2<0.5,"L0 — Inicial",IF(H2<1.5,"L1 — Em Desenvolvimento",IF(H2<2.5,"L2 — Definido",IF(H2<3.5,"L3 — Gerenciado","L4 — Otimizando"))))) | J2: 4 | K2: =IF(H2="","",MAX(0,J2-H2)) | L2: =IF(K2="","",D2*K2) | M2: =IF(L2="","",IF(L2>=2.4,"P0 — Crítico",IF(L2>=1.6,"P1 — Alto",IF(L2>=0.9,"P2 — Médio","P3 — Baixo")))) | N2: =IF(H2="",0,H2*D2) | O2: =IF(H2="",0,D2)
A3: P1-C2 | B3: Plataforma de Experiência do Desenvolvedor | C3: P1 | D3: 1 | E3: =COUNTIFS('Respostas'!$C$2:$C$159,A3,'Respostas'!$G$2:$G$159,1) | F3: =SUMIFS('Respostas'!$H$2:$H$159,'Respostas'!$C$2:$C$159,A3) | G3: =SUMIFS('Respostas'!$F$2:$F$159,'Respostas'!$C$2:$C$159,A3,'Respostas'!$G$2:$G$159,1) | H3: =IF(G3=0,"",F3/G3) | I3: =IF(H3="","—",IF(H3<0.5,"L0 — Inicial",IF(H3<1.5,"L1 — Em Desenvolvimento",IF(H3<2.5,"L2 — Definido",IF(H3<3.5,"L3 — Gerenciado","L4 — Otimizando"))))) | J3: 3 | K3: =IF(H3="","",MAX(0,J3-H3)) | L3: =IF(K3="","",D3*K3) | M3: =IF(L3="","",IF(L3>=2.4,"P0 — Crítico",IF(L3>=1.6,"P1 — Alto",IF(L3>=0.9,"P2 — Médio","P3 — Baixo")))) | N3: =IF(H3="",0,H3*D3) | O3: =IF(H3="",0,D3)
A4: P1-C3 | B4: Gestão do Conhecimento | C4: P1 | D4: 0.8 | E4: =COUNTIFS('Respostas'!$C$2:$C$159,A4,'Respostas'!$G$2:$G$159,1) | F4: =SUMIFS('Respostas'!$H$2:$H$159,'Respostas'!$C$2:$C$159,A4) | G4: =SUMIFS('Respostas'!$F$2:$F$159,'Respostas'!$C$2:$C$159,A4,'Respostas'!$G$2:$G$159,1) | H4: =IF(G4=0,"",F4/G4) | I4: =IF(H4="","—",IF(H4<0.5,"L0 — Inicial",IF(H4<1.5,"L1 — Em Desenvolvimento",IF(H4<2.5,"L2 — Definido",IF(H4<3.5,"L3 — Gerenciado","L4 — Otimizando"))))) | J4: 3 | K4: =IF(H4="","",MAX(0,J4-H4)) | L4: =IF(K4="","",D4*K4) | M4: =IF(L4="","",IF(L4>=2.4,"P0 — Crítico",IF(L4>=1.6,"P1 — Alto",IF(L4>=0.9,"P2 — Médio","P3 — Baixo")))) | N4: =IF(H4="",0,H4*D4) | O4: =IF(H4="",0,D4)
A5: P1-C4 | B5: Automação de Revisão de Código | C5: P1 | D5: 1.1 | E5: =COUNTIFS('Respostas'!$C$2:$C$159,A5,'Respostas'!$G$2:$G$159,1) | F5: =SUMIFS('Respostas'!$H$2:$H$159,'Respostas'!$C$2:$C$159,A5) | G5: =SUMIFS('Respostas'!$F$2:$F$159,'Respostas'!$C$2:$C$159,A5,'Respostas'!$G$2:$G$159,1) | H5: =IF(G5=0,"",F5/G5) | I5: =IF(H5="","—",IF(H5<0.5,"L0 — Inicial",IF(H5<1.5,"L1 — Em Desenvolvimento",IF(H5<2.5,"L2 — Definido",IF(H5<3.5,"L3 — Gerenciado","L4 — Otimizando"))))) | J5: 3 | K5: =IF(H5="","",MAX(0,J5-H5)) | L5: =IF(K5="","",D5*K5) | M5: =IF(L5="","",IF(L5>=2.4,"P0 — Crítico",IF(L5>=1.6,"P1 — Alto",IF(L5>=0.9,"P2 — Médio","P3 — Baixo")))) | N5: =IF(H5="",0,H5*D5) | O5: =IF(H5="",0,D5)
A6: P1-C5 | B6: Onboarding e Treinamento de Desenvolvedores | C6: P1 | D6: 0.9 | E6: =COUNTIFS('Respostas'!$C$2:$C$159,A6,'Respostas'!$G$2:$G$159,1) | F6: =SUMIFS('Respostas'!$H$2:$H$159,'Respostas'!$C$2:$C$159,A6) | G6: =SUMIFS('Respostas'!$F$2:$F$159,'Respostas'!$C$2:$C$159,A6,'Respostas'!$G$2:$G$159,1) | H6: =IF(G6=0,"",F6/G6) | I6: =IF(H6="","—",IF(H6<0.5,"L0 — Inicial",IF(H6<1.5,"L1 — Em Desenvolvimento",IF(H6<2.5,"L2 — Definido",IF(H6<3.5,"L3 — Gerenciado","L4 — Otimizando"))))) | J6: 3 | K6: =IF(H6="","",MAX(0,J6-H6)) | L6: =IF(K6="","",D6*K6) | M6: =IF(L6="","",IF(L6>=2.4,"P0 — Crítico",IF(L6>=1.6,"P1 — Alto",IF(L6>=0.9,"P2 — Médio","P3 — Baixo")))) | N6: =IF(H6="",0,H6*D6) | O6: =IF(H6="",0,D6)
A7: P1-C6 | B7: Inner Source e Colaboração | C7: P1 | D7: 0.9 | E7: =COUNTIFS('Respostas'!$C$2:$C$159,A7,'Respostas'!$G$2:$G$159,1) | F7: =SUMIFS('Respostas'!$H$2:$H$159,'Respostas'!$C$2:$C$159,A7) | G7: =SUMIFS('Respostas'!$F$2:$F$159,'Respostas'!$C$2:$C$159,A7,'Respostas'!$G$2:$G$159,1) | H7: =IF(G7=0,"",F7/G7) | I7: =IF(H7="","—",IF(H7<0.5,"L0 — Inicial",IF(H7<1.5,"L1 — Em Desenvolvimento",IF(H7<2.5,"L2 — Definido",IF(H7<3.5,"L3 — Gerenciado","L4 — Otimizando"))))) | J7: 3 | K7: =IF(H7="","",MAX(0,J7-H7)) | L7: =IF(K7="","",D7*K7) | M7: =IF(L7="","",IF(L7>=2.4,"P0 — Crítico",IF(L7>=1.6,"P1 — Alto",IF(L7>=0.9,"P2 — Médio","P3 — Baixo")))) | N7: =IF(H7="",0,H7*D7) | O7: =IF(H7="",0,D7)
A8: P1-C7 | B8: Automação de Documentação | C8: P1 | D8: 0.8 | E8: =COUNTIFS('Respostas'!$C$2:$C$159,A8,'Respostas'!$G$2:$G$159,1) | F8: =SUMIFS('Respostas'!$H$2:$H$159,'Respostas'!$C$2:$C$159,A8) | G8: =SUMIFS('Respostas'!$F$2:$F$159,'Respostas'!$C$2:$C$159,A8,'Respostas'!$G$2:$G$159,1) | H8: =IF(G8=0,"",F8/G8) | I8: =IF(H8="","—",IF(H8<0.5,"L0 — Inicial",IF(H8<1.5,"L1 — Em Desenvolvimento",IF(H8<2.5,"L2 — Definido",IF(H8<3.5,"L3 — Gerenciado","L4 — Otimizando"))))) | J8: 3 | K8: =IF(H8="","",MAX(0,J8-H8)) | L8: =IF(K8="","",D8*K8) | M8: =IF(L8="","",IF(L8>=2.4,"P0 — Crítico",IF(L8>=1.6,"P1 — Alto",IF(L8>=0.9,"P2 — Médio","P3 — Baixo")))) | N8: =IF(H8="",0,H8*D8) | O8: =IF(H8="",0,D8)
A9: P1-C8 | B9: Medição de Produtividade do Desenvolvedor | C9: P1 | D9: 1 | E9: =COUNTIFS('Respostas'!$C$2:$C$159,A9,'Respostas'!$G$2:$G$159,1) | F9: =SUMIFS('Respostas'!$H$2:$H$159,'Respostas'!$C$2:$C$159,A9) | G9: =SUMIFS('Respostas'!$F$2:$F$159,'Respostas'!$C$2:$C$159,A9,'Respostas'!$G$2:$G$159,1) | H9: =IF(G9=0,"",F9/G9) | I9: =IF(H9="","—",IF(H9<0.5,"L0 — Inicial",IF(H9<1.5,"L1 — Em Desenvolvimento",IF(H9<2.5,"L2 — Definido",IF(H9<3.5,"L3 — Gerenciado","L4 — Otimizando"))))) | J9: 3 | K9: =IF(H9="","",MAX(0,J9-H9)) | L9: =IF(K9="","",D9*K9) | M9: =IF(L9="","",IF(L9>=2.4,"P0 — Crítico",IF(L9>=1.6,"P1 — Alto",IF(L9>=0.9,"P2 — Médio","P3 — Baixo")))) | N9: =IF(H9="",0,H9*D9) | O9: =IF(H9="",0,D9)
A10: P1-C9 | B10: Automação de Ambientes e Espaços de Trabalho | C10: P1 | D10: 0.9 | E10: =COUNTIFS('Respostas'!$C$2:$C$159,A10,'Respostas'!$G$2:$G$159,1) | F10: =SUMIFS('Respostas'!$H$2:$H$159,'Respostas'!$C$2:$C$159,A10) | G10: =SUMIFS('Respostas'!$F$2:$F$159,'Respostas'!$C$2:$C$159,A10,'Respostas'!$G$2:$G$159,1) | H10: =IF(G10=0,"",F10/G10) | I10: =IF(H10="","—",IF(H10<0.5,"L0 — Inicial",IF(H10<1.5,"L1 — Em Desenvolvimento",IF(H10<2.5,"L2 — Definido",IF(H10<3.5,"L3 — Gerenciado","L4 — Otimizando"))))) | J10: 3 | K10: =IF(H10="","",MAX(0,J10-H10)) | L10: =IF(K10="","",D10*K10) | M10: =IF(L10="","",IF(L10>=2.4,"P0 — Crítico",IF(L10>=1.6,"P1 — Alto",IF(L10>=0.9,"P2 — Médio","P3 — Baixo")))) | N10: =IF(H10="",0,H10*D10) | O10: =IF(H10="",0,D10)
A11: P2-C1 | B11: Inteligência de Pipeline CI/CD | C11: P2 | D11: 1.2 | E11: =COUNTIFS('Respostas'!$C$2:$C$159,A11,'Respostas'!$G$2:$G$159,1) | F11: =SUMIFS('Respostas'!$H$2:$H$159,'Respostas'!$C$2:$C$159,A11) | G11: =SUMIFS('Respostas'!$F$2:$F$159,'Respostas'!$C$2:$C$159,A11,'Respostas'!$G$2:$G$159,1) | H11: =IF(G11=0,"",F11/G11) | I11: =IF(H11="","—",IF(H11<0.5,"L0 — Inicial",IF(H11<1.5,"L1 — Em Desenvolvimento",IF(H11<2.5,"L2 — Definido",IF(H11<3.5,"L3 — Gerenciado","L4 — Otimizando"))))) | J11: 3 | K11: =IF(H11="","",MAX(0,J11-H11)) | L11: =IF(K11="","",D11*K11) | M11: =IF(L11="","",IF(L11>=2.4,"P0 — Crítico",IF(L11>=1.6,"P1 — Alto",IF(L11>=0.9,"P2 — Médio","P3 — Baixo")))) | N11: =IF(H11="",0,H11*D11) | O11: =IF(H11="",0,D11)
A12: P2-C2 | B12: Infraestrutura como Código | C12: P2 | D12: 1.1 | E12: =COUNTIFS('Respostas'!$C$2:$C$159,A12,'Respostas'!$G$2:$G$159,1) | F12: =SUMIFS('Respostas'!$H$2:$H$159,'Respostas'!$C$2:$C$159,A12) | G12: =SUMIFS('Respostas'!$F$2:$F$159,'Respostas'!$C$2:$C$159,A12,'Respostas'!$G$2:$G$159,1) | H12: =IF(G12=0,"",F12/G12) | I12: =IF(H12="","—",IF(H12<0.5,"L0 — Inicial",IF(H12<1.5,"L1 — Em Desenvolvimento",IF(H12<2.5,"L2 — Definido",IF(H12<3.5,"L3 — Gerenciado","L4 — Otimizando"))))) | J12: 3 | K12: =IF(H12="","",MAX(0,J12-H12)) | L12: =IF(K12="","",D12*K12) | M12: =IF(L12="","",IF(L12>=2.4,"P0 — Crítico",IF(L12>=1.6,"P1 — Alto",IF(L12>=0.9,"P2 — Médio","P3 — Baixo")))) | N12: =IF(H12="",0,H12*D12) | O12: =IF(H12="",0,D12)
A13: P2-C3 | B13: Observabilidade e Monitoramento | C13: P2 | D13: 1 | E13: =COUNTIFS('Respostas'!$C$2:$C$159,A13,'Respostas'!$G$2:$G$159,1) | F13: =SUMIFS('Respostas'!$H$2:$H$159,'Respostas'!$C$2:$C$159,A13) | G13: =SUMIFS('Respostas'!$F$2:$F$159,'Respostas'!$C$2:$C$159,A13,'Respostas'!$G$2:$G$159,1) | H13: =IF(G13=0,"",F13/G13) | I13: =IF(H13="","—",IF(H13<0.5,"L0 — Inicial",IF(H13<1.5,"L1 — Em Desenvolvimento",IF(H13<2.5,"L2 — Definido",IF(H13<3.5,"L3 — Gerenciado","L4 — Otimizando"))))) | J13: 3 | K13: =IF(H13="","",MAX(0,J13-H13)) | L13: =IF(K13="","",D13*K13) | M13: =IF(L13="","",IF(L13>=2.4,"P0 — Crítico",IF(L13>=1.6,"P1 — Alto",IF(L13>=0.9,"P2 — Médio","P3 — Baixo")))) | N13: =IF(H13="",0,H13*D13) | O13: =IF(H13="",0,D13)
... A29: P3-C9 | B29: FinOps e Otimização de Custos | C29: P3 | D29: 0.9 | E29: =COUNTIFS('Respostas'!$C$2:$C$159,A29,'Respostas'!$G$2:$G$159,1) | F29: =SUMIFS('Respostas'!$H$2:$H$159,'Respostas'!$C$2:$C$159,A29) | G29: =SUMIFS('Respostas'!$F$2:$F$159,'Respostas'!$C$2:$C$159,A29,'Respostas'!$G$2:$G$159,1) | H29: =IF(G29=0,"",F29/G29) | I29: =IF(H29="","—",IF(H29<0.5,"L0 — Inicial",IF(H29<1.5,"L1 — Em Desenvolvimento",IF(H29<2.5,"L2 — Definido",IF(H29<3.5,"L3 — Gerenciado","L4 — Otimizando"))))) | J29: 3 | K29: =IF(H29="","",MAX(0,J29-H29)) | L29: =IF(K29="","",D29*K29) | M29: =IF(L29="","",IF(L29>=2.4,"P0 — Crítico",IF(L29>=1.6,"P1 — Alto",IF(L29>=0.9,"P2 — Médio","P3 — Baixo")))) | N29: =IF(H29="",0,H29*D29) | O29: =IF(H29="",0,D29)

Sheet Pilares e Overall
A1: Pilar | B1: Nome | C1: Score | D1: Rótulo
A2: P1 | B2: Produtividade do Desenvolvedor | C2: =IFERROR(SUMIFS('Capabilities'!$N$2:$N$29,'Capabilities'!$C$2:$C$29,A2)/SUMIFS('Capabilities'!$O$2:$O$29,'Capabilities'!$C$2:$C$29,A2),0) | D2: =IF(C2="","—",IF(C2<0.5,"L0 — Inicial",IF(C2<1.5,"L1 — Em Desenvolvimento",IF(C2<2.5,"L2 — Definido",IF(C2<3.5,"L3 — Gerenciado","L4 — Otimizando")))))
A3: P2 | B3: Ciclo de Vida DevOps | C3: =IFERROR(SUMIFS('Capabilities'!$N$2:$N$29,'Capabilities'!$C$2:$C$29,A3)/SUMIFS('Capabilities'!$O$2:$O$29,'Capabilities'!$C$2:$C$29,A3),0) | D3: =IF(C3="","—",IF(C3<0.5,"L0 — Inicial",IF(C3<1.5,"L1 — Em Desenvolvimento",IF(C3<2.5,"L2 — Definido",IF(C3<3.5,"L3 — Gerenciado","L4 — Otimizando")))))
A4: P3 | B4: Plataforma de Aplicações | C4: =IFERROR(SUMIFS('Capabilities'!$N$2:$N$29,'Capabilities'!$C$2:$C$29,A4)/SUMIFS('Capabilities'!$O$2:$O$29,'Capabilities'!$C$2:$C$29,A4),0) | D4: =IF(C4="","—",IF(C4<0.5,"L0 — Inicial",IF(C4<1.5,"L1 — Em Desenvolvimento",IF(C4<2.5,"L2 — Definido",IF(C4<3.5,"L3 — Gerenciado","L4 — Otimizando")))))
A6: OVERALL | C6: =IFERROR(SUM('Capabilities'!$N$2:$N$29)/SUM('Capabilities'!$O$2:$O$29),"") | D6: =IF(C6="","—",IF(C6<0.5,"L0 — Inicial",IF(C6<1.5,"L1 — Em Desenvolvimento",IF(C6<2.5,"L2 — Definido",IF(C6<3.5,"L3 — Gerenciado","L4 — Otimizando")))))
A7: Questões respondidas | C7: =SUM('Respostas'!$G$2:$G$159)
A8: Status de cobertura | C8: =IF(C7>=40,"OK",IF(C7>=25,"WARNING","BLOCKED"))
